Failure # 1 (occurred at 2021-10-11_12-22-48)
Traceback (most recent call last):
  File "E:\anaconda\envs\logitech\lib\site-packages\ray\tune\trial_runner.py", line 739, in _process_trial
    results = self.trial_executor.fetch_result(trial)
  File "E:\anaconda\envs\logitech\lib\site-packages\ray\tune\ray_trial_executor.py", line 746, in fetch_result
    result = ray.get(trial_future[0], timeout=DEFAULT_GET_TIMEOUT)
  File "E:\anaconda\envs\logitech\lib\site-packages\ray\_private\client_mode_hook.py", line 82, in wrapper
    return func(*args, **kwargs)
  File "E:\anaconda\envs\logitech\lib\site-packages\ray\worker.py", line 1621, in get
    raise value.as_instanceof_cause()
ray.exceptions.RayTaskError(ValueError): [36mray::SAC.train()[39m (pid=12912, ip=172.22.22.55, repr=SAC)
  File "python\ray\_raylet.pyx", line 536, in ray._raylet.execute_task
  File "python\ray\_raylet.pyx", line 486, in ray._raylet.execute_task.function_executor
  File "E:\anaconda\envs\logitech\lib\site-packages\ray\_private\function_manager.py", line 563, in actor_method_executor
    return method(__ray_actor, *args, **kwargs)
  File "E:\anaconda\envs\logitech\lib\site-packages\ray\rllib\agents\trainer.py", line 648, in train
    raise e
  File "E:\anaconda\envs\logitech\lib\site-packages\ray\rllib\agents\trainer.py", line 637, in train
    result = Trainable.train(self)
  File "E:\anaconda\envs\logitech\lib\site-packages\ray\tune\trainable.py", line 237, in train
    result = self.step()
  File "E:\anaconda\envs\logitech\lib\site-packages\ray\rllib\agents\trainer_template.py", line 193, in step
    res = next(self.train_exec_impl)
  File "E:\anaconda\envs\logitech\lib\site-packages\ray\util\iter.py", line 756, in __next__
    return next(self.built_iterator)
  File "E:\anaconda\envs\logitech\lib\site-packages\ray\util\iter.py", line 783, in apply_foreach
    for item in it:
  File "E:\anaconda\envs\logitech\lib\site-packages\ray\util\iter.py", line 843, in apply_filter
    for item in it:
  File "E:\anaconda\envs\logitech\lib\site-packages\ray\util\iter.py", line 843, in apply_filter
    for item in it:
  File "E:\anaconda\envs\logitech\lib\site-packages\ray\util\iter.py", line 783, in apply_foreach
    for item in it:
  File "E:\anaconda\envs\logitech\lib\site-packages\ray\util\iter.py", line 843, in apply_filter
    for item in it:
  File "E:\anaconda\envs\logitech\lib\site-packages\ray\util\iter.py", line 1075, in build_union
    item = next(it)
  File "E:\anaconda\envs\logitech\lib\site-packages\ray\util\iter.py", line 756, in __next__
    return next(self.built_iterator)
  File "E:\anaconda\envs\logitech\lib\site-packages\ray\util\iter.py", line 783, in apply_foreach
    for item in it:
  File "E:\anaconda\envs\logitech\lib\site-packages\ray\util\iter.py", line 783, in apply_foreach
    for item in it:
  File "E:\anaconda\envs\logitech\lib\site-packages\ray\util\iter.py", line 783, in apply_foreach
    for item in it:
  [Previous line repeated 1 more time]
  File "E:\anaconda\envs\logitech\lib\site-packages\ray\util\iter.py", line 471, in base_iterator
    yield ray.get(futures, timeout=timeout)
  File "E:\anaconda\envs\logitech\lib\site-packages\ray\_private\client_mode_hook.py", line 82, in wrapper
    return func(*args, **kwargs)
  File "E:\anaconda\envs\logitech\lib\site-packages\ray\worker.py", line 1621, in get
    raise value.as_instanceof_cause()
ray.exceptions.RayTaskError(ValueError): [36mray::RolloutWorker.par_iter_next()[39m (pid=10552, ip=172.22.22.55, repr=<ray.rllib.evaluation.rollout_worker.RolloutWorker object at 0x000002A796721760>)
  File "python\ray\_raylet.pyx", line 536, in ray._raylet.execute_task
  File "python\ray\_raylet.pyx", line 486, in ray._raylet.execute_task.function_executor
  File "E:\anaconda\envs\logitech\lib\site-packages\ray\_private\function_manager.py", line 563, in actor_method_executor
    return method(__ray_actor, *args, **kwargs)
  File "E:\anaconda\envs\logitech\lib\site-packages\ray\util\iter.py", line 1151, in par_iter_next
    return next(self.local_it)
  File "E:\anaconda\envs\logitech\lib\site-packages\ray\rllib\evaluation\rollout_worker.py", line 346, in gen_rollouts
    yield self.sample()
  File "E:\anaconda\envs\logitech\lib\site-packages\ray\rllib\evaluation\rollout_worker.py", line 744, in sample
    batches = [self.input_reader.next()]
  File "E:\anaconda\envs\logitech\lib\site-packages\ray\rllib\evaluation\sampler.py", line 101, in next
    batches = [self.get_data()]
  File "E:\anaconda\envs\logitech\lib\site-packages\ray\rllib\evaluation\sampler.py", line 231, in get_data
    item = next(self.rollout_provider)
  File "E:\anaconda\envs\logitech\lib\site-packages\ray\rllib\evaluation\sampler.py", line 601, in _env_runner
    _process_observations(
  File "E:\anaconda\envs\logitech\lib\site-packages\ray\rllib\evaluation\sampler.py", line 820, in _process_observations
    prep_obs: EnvObsType = _get_or_raise(worker.preprocessors,
  File "E:\anaconda\envs\logitech\lib\site-packages\ray\rllib\models\preprocessors.py", line 187, in transform
    self.check_shape(observation)
  File "E:\anaconda\envs\logitech\lib\site-packages\ray\rllib\models\preprocessors.py", line 66, in check_shape
    raise ValueError(
ValueError: ('Observation ({}) outside given space ({})!', array([-0.618     , -0.78      , -0.808     ,  1.        , -0.464     ,
       -0.78      , -0.768     , -1.        ,  0.        , -0.01933287]), Box([-1. -1. -1. -1. -1. -1. -1. -1. -1. -1.], [1. 1. 1. 1. 1. 1. 1. 1. 1. 1.], (10,), float32))

